Workbook

Sheet 总表
A1: 等级 | B1: 当前等级经验 | C1: 经验修正值 | D1: 预计杀怪数 | E1: 当前等级天数 | F1: 累计升级天数 | G1: 杀怪经验 | H1: 任务经验 | I1: 对应副本 | K1: 副本升级经验
A2: 1 | B2: =G2+H2+K2 -> 225 | C2: =ROUND(B2,-2) -> 200 | D2: 5 | E2: =D2/$R$4 -> 0.005 | F2: =SUM($E$2:E2) -> 0.005 | G2: =D2*怪物经验!C2 -> 75 | H2: =任务经验!F2 -> 150 | I2: 0 | J2: 0 | K2: =J2*E2 -> 0 | M2: 225 | Q2: 每日体力 | R2: 100
A3: 2 | B3: =G3+H3+K3 -> 500 | C3: =ROUND(B3,-2) -> 500 | D3: 10 | E3: =D3/$R$4 -> 0.01 | F3: =SUM($E$2:E3) -> 0.015 | G3: =D3*怪物经验!C3 -> 200 | H3: =任务经验!F3 -> 300 | I3: 0 | J3: 0 | K3: =J3*E3 -> 0 | M3: 500 | Q3: 体力兑换杀怪数 | R3: 10
A4: 3 | B4: =G4+H4+K4 -> 1125 | C4: =ROUND(B4,-2) -> 1100 | D4: 20 | E4: =D4/$R$4 -> 0.02 | F4: =SUM($E$2:E4) -> 0.035 | G4: =D4*怪物经验!C4 -> 500 | H4: =任务经验!F4 -> 625 | I4: 0 | J4: 0 | K4: =J4*E4 -> 0 | M4: 1125 | Q4: 每日杀怪数 | R4: =R3*R2 -> 1000
A5: 4 | B5: =G5+H5+K5 -> 1350 | C5: =ROUND(B5,-2) -> 1400 | D5: 30 | E5: =D5/$R$4 -> 0.03 | F5: =SUM($E$2:E5) -> 0.065 | G5: =D5*怪物经验!C5 -> 900 | H5: =任务经验!F5 -> 450 | I5: 0 | J5: 0 | K5: =J5*E5 -> 0 | M5: 1350 | Q5: 每日副本次数 | R5: 5
A6: 5 | B6: =G6+H6+K6 -> 2600 | C6: =ROUND(B6,-2) -> 2600 | D6: 50 | E6: =D6/$R$4 -> 0.05 | F6: =SUM($E$2:E6) -> 0.115 | G6: =D6*怪物经验!C6 -> 2000 | H6: =任务经验!F6 -> 600 | I6: 0 | J6: 0 | K6: =J6*E6 -> 0 | M6: 2600
A7: 6 | B7: =G7+H7+K7 -> 4250 | C7: =ROUND(B7,-2) -> 4300 | D7: =D6+25 -> 75 | E7: =D7/$R$4 -> 0.075 | F7: =SUM($E$2:E7) -> 0.19 | G7: =D7*怪物经验!C7 -> 3750 | H7: =任务经验!F7 -> 500 | I7: 0 | J7: 0 | K7: =J7*E7 -> 0 | M7: 4250
A8: 7 | B8: =G8+H8+K8 -> 6600 | C8: =ROUND(B8,-2) -> 6600 | D8: 100 | E8: =D8/$R$4 -> 0.1 | F8: =SUM($E$2:E8) -> 0.29 | G8: =D8*怪物经验!C8 -> 6000 | H8: =任务经验!F8 -> 600 | I8: 0 | J8: 0 | K8: =J8*E8 -> 0 | M8: 6600 | Q8: 体力规划 | R8: 0点 | S8: 40 | T8: 0点 | U8: 30 | W8: =120/24 -> 5
A9: 8 | B9: =G9+H9+K9 -> 8400 | C9: =ROUND(B9,-2) -> 8400 | D9: =D8+10 -> 110 | E9: =D9/$R$4 -> 0.11 | F9: =SUM($E$2:E9) -> 0.4 | G9: =D9*怪物经验!C9 -> 7700 | H9: =任务经验!F9 -> 700 | I9: 0 | J9: 0 | K9: =J9*E9 -> 0 | M9: 8400 | R9: 12点 | S9: 40 | T9: 6点 | U9: 30 | W9: 5
A10: 9 | B10: =G10+H10+K10 -> 10000 | C10: =ROUND(B10,-2) -> 10000 | D10: =D9+10 -> 120 | E10: =D10/$R$4 -> 0.12 | F10: =SUM($E$2:E10) -> 0.52 | G10: =D10*怪物经验!C10 -> 9600 | H10: =任务经验!F10 -> 400 | I10: 0 | J10: 0 | K10: =J10*E10 -> 0 | M10: 10000 | R10: 月卡 | S10: 20 | T10: 12点 | U10: 30 | W10: 24
A11: 10 | B11: =G11+H11+K11 -> 12825 | C11: =ROUND(B11,-2) -> 12800 | D11: =D10+10 -> 130 | E11: =D11/$R$4 -> 0.13 | F11: =SUM($E$2:E11) -> 0.65 | G11: =D11*怪物经验!C11 -> 12350 | H11: =任务经验!F11 -> 475 | I11: 0 | J11: 0 | K11: =J11*E11 -> 0 | M11: 12825 | R11: 每日任务 | S11: 20 | T11: 20点 | U11: 30 | W11: =W10*W9 -> 120
A12: 11 | B12: =G12+H12+K12 -> 16060 | C12: =ROUND(B12,-2) -> 16100 | D12: =D11+10 -> 140 | E12: =D12/$R$4 -> 0.14 | F12: =SUM($E$2:E12) -> 0.79 | G12: =D12*怪物经验!C12 -> 15400 | H12: =任务经验!F12 -> 660 | I12: 0 | J12: 0 | K12: =J12*E12 -> 0 | M12: 16060 | T12: 月卡 | U12: 20
A13: 12 | B13: =G13+H13+K13 -> 19500 | C13: =ROUND(B13,-2) -> 19500 | D13: =D12+10 -> 150 | E13: =D13/$R$4 -> 0.15 | F13: =SUM($E$2:E13) -> 0.94 | G13: =D13*怪物经验!C13 -> 18750 | H13: =任务经验!F13 -> 750 | I13: 0 | J13: 0 | K13: =J13*E13 -> 0 | M13: 19500 | T13: 每日签到 | U13: 20
A14: 13 | B14: =G14+H14+K14 -> 22400 | C14: =ROUND(B14,-2) -> 22400 | D14: =D13+10 -> 160 | E14: =D14/$R$4 -> 0.16 | F14: =SUM($E$2:E14) -> 1.1 | G14: =D14*怪物经验!C14 -> 22400 | H14: =任务经验!F14 -> 0 | I14: 0 | J14: 0 | K14: =J14*E14 -> 0 | M14: 22400 | S14: =SUM(S8:S11) -> 120 | T14: 每日任务 | U14: 40
A15: 14 | B15: =G15+H15+K15 -> 27280 | C15: =ROUND(B15,-2) -> 27300 | D15: =D14+10 -> 170 | E15: =D15/$R$4 -> 0.17 | F15: =SUM($E$2:E15) -> 1.27 | G15: =D15*怪物经验!C15 -> 26350 | H15: =任务经验!F15 -> 930 | I15: 0 | J15: 0 | K15: =J15*E15 -> 0 | M15: 27280
A16: 15 | B16: =G16+H16+K16 -> 47420 | C16: =ROUND(B16,-2) -> 47400 | D16: 100 | E16: =D16/$R$4 -> 0.1 | F16: =SUM($E$2:E16) -> 1.37 | G16: =D16*怪物经验!C16 -> 17000 | H16: =任务经验!F16 -> 1020 | I16: 20 | J16: =LOOKUP(I16,组队副本!A:A,组队副本!I:I) -> 58800 | K16: =J16*E16*$R$5 -> 29400 | M16: 47420 | T16: 总 | U16: =SUM(U8:U14) -> 200
A17: 16 | B17: =G17+H17+K17 -> 54380 | C17: =ROUND(B17,-2) -> 54400 | D17: =D16+10 -> 110 | E17: =D17/$R$4 -> 0.11 | F17: =SUM($E$2:E17) -> 1.48 | G17: =D17*怪物经验!C17 -> 20900 | H17: =任务经验!F17 -> 1140 | I17: 20 | J17: =LOOKUP(I17,组队副本!A:A,组队副本!I:I) -> 58800 | K17: =J17*E17*$R$5 -> 32340 | M17: 54380
A18: 17 | B18: =G18+H18+K18 -> 61740 | C18: =ROUND(B18,-2) -> 61700 | D18: =D17+10 -> 120 | E18: =D18/$R$4 -> 0.12 | F18: =SUM($E$2:E18) -> 1.6 | G18: =D18*怪物经验!C18 -> 25200 | H18: =任务经验!F18 -> 1260 | I18: 20 | J18: =LOOKUP(I18,组队副本!A:A,组队副本!I:I) -> 58800 | K18: =J18*E18*$R$5 -> 35280 | M18: 61740
A19: 18 | B19: =G19+H19+K19 -> 69500 | C19: =ROUND(B19,-2) -> 69500 | D19: =D18+10 -> 130 | E19: =D19/$R$4 -> 0.13 | F19: =SUM($E$2:E19) -> 1.73 | G19: =D19*怪物经验!C19 -> 29900 | H19: =任务经验!F19 -> 1380 | I19: 20 | J19: =LOOKUP(I19,组队副本!A:A,组队副本!I:I) -> 58800 | K19: =J19*E19*$R$5 -> 38220 | M19: 69500
A20: 19 | B20: =G20+H20+K20 -> 110300 | C20: =ROUND(B20,-2) -> 110300 | D20: 200 | E20: =D20/$R$4 -> 0.2 | F20: =SUM($E$2:E20) -> 1.93 | G20: =D20*怪物经验!C20 -> 50000 | H20: =任务经验!F20 -> 1500 | I20: 20 | J20: =LOOKUP(I20,组队副本!A:A,组队副本!I:I) -> 58800 | K20: =J20*E20*$R$5 -> 58800 | M20: 110300
A21: 20 | B21: =G21+H21+K21 -> 122220 | C21: =ROUND(B21,-2) -> 122200 | D21: =D20+10 -> 210 | E21: =D21/$R$4 -> 0.21 | F21: =SUM($E$2:E21) -> 2.14 | G21: =D21*怪物经验!C21 -> 58800 | H21: =任务经验!F21 -> 1680 | I21: 20 | J21: =LOOKUP(I21,组队副本!A:A,组队副本!I:I) -> 58800 | K21: =J21*E21*$R$5 -> 61740 | M21: 122220
A22: 21 | B22: =G22+H22+K22 -> 135050 | C22: =ROUND(B22,-2) -> 135100 | D22: =D21+10 -> 220 | E22: =D22/$R$4 -> 0.22 | F22: =SUM($E$2:E22) -> 2.36 | G22: =D22*怪物经验!C22 -> 68200 | H22: =任务经验!F22 -> 2170 | I22: 20 | J22: =LOOKUP(I22,组队副本!A:A,组队副本!I:I) -> 58800 | K22: =J22*E22*$R$5 -> 64680 | M22: 135050
A23: 22 | B23: =G23+H23+K23 -> 148200 | C23: =ROUND(B23,-2) -> 148200 | D23: =D22+10 -> 230 | E23: =D23/$R$4 -> 0.23 | F23: =SUM($E$2:E23) -> 2.59 | G23: =D23*怪物经验!C23 -> 78200 | H23: =任务经验!F23 -> 2380 | I23: 20 | J23: =LOOKUP(I23,组队副本!A:A,组队副本!I:I) -> 58800 | K23: =J23*E23*$R$5 -> 67620 | M23: 148200
A24: 23 | B24: =G24+H24+K24 -> 161950 | C24: =ROUND(B24,-2) -> 162000 | D24: =D23+10 -> 240 | E24: =D24/$R$4 -> 0.24 | F24: =SUM($E$2:E24) -> 2.83 | G24: =D24*怪物经验!C24 -> 88800 | H24: =任务经验!F24 -> 2590 | I24: 20 | J24: =LOOKUP(I24,组队副本!A:A,组队副本!I:I) -> 58800 | K24: =J24*E24*$R$5 -> 70560 | M24: 161950
A25: 24 | B25: =G25+H25+K25 -> 176300 | C25: =ROUND(B25,-2) -> 176300 | D25: =D24+10 -> 250 | E25: =D25/$R$4 -> 0.25 | F25: =SUM($E$2:E25) -> 3.08 | G25: =D25*怪物经验!C25 -> 100000 | H25: =任务经验!F25 -> 2800 | I25: 20 | J25: =LOOKUP(I25,组队副本!A:A,组队副本!I:I) -> 58800 | K25: =J25*E25*$R$5 -> 73500 | M25: 176300
A26: 25 | B26: =G26+H26+K26 -> 191250 | C26: =ROUND(B26,-2) -> 191300 | D26: =D25+10 -> 260 | E26: =D26/$R$4 -> 0.26 | F26: =SUM($E$2:E26) -> 3.34 | G26: =D26*怪物经验!C26 -> 111800 | H26: =任务经验!F26 -> 3010 | I26: 20 | J26: =LOOKUP(I26,组队副本!A:A,组队副本!I:I) -> 58800 | K26: =J26*E26*$R$5 -> 76440 | M26: 191250
A27: 26 | B27: =G27+H27+K27 -> 207260 | C27: =ROUND(B27,-2) -> 207300 | D27: =D26+10 -> 270 | E27: =D27/$R$4 -> 0.27 | F27: =SUM($E$2:E27) -> 3.61 | G27: =D27*怪物经验!C27 -> 124200 | H27: =任务经验!F27 -> 3680 | I27: 20 | J27: =LOOKUP(I27,组队副本!A:A,组队副本!I:I) -> 58800 | K27: =J27*E27*$R$5 -> 79380 | M27: 207260
A28: 27 | B28: =G28+H28+K28 -> 223440 | C28: =ROUND(B28,-2) -> 223400 | D28: =D27+10 -> 280 | E28: =D28/$R$4 -> 0.28 | F28: =SUM($E$2:E28) -> 3.89 | G28: =D28*怪物经验!C28 -> 137200 | H28: =任务经验!F28 -> 3920 | I28: 20 | J28: =LOOKUP(I28,组队副本!A:A,组队副本!I:I) -> 58800 | K28: =J28*E28*$R$5 -> 82320 | M28: 223440
A29: 28 | B29: =G29+H29+K29 -> 240220 | C29: =ROUND(B29,-2) -> 240200 | D29: =D28+10 -> 290 | E29: =D29/$R$4 -> 0.29 | F29: =SUM($E$2:E29) -> 4.18 | G29: =D29*怪物经验!C29 -> 150800 | H29: =任务经验!F29 -> 4160 | I29: 20 | J29: =LOOKUP(I29,组队副本!A:A,组队副本!I:I) -> 58800 | K29: =J29*E29*$R$5 -> 85260 | M29: 240220
A30: 29 | B30: =G30+H30+K30 -> 299800 | C30: =ROUND(B30,-2) -> 299800 | D30: 350 | E30: =D30/$R$4 -> 0.35 | F30: =SUM($E$2:E30) -> 4.53 | G30: =D30*怪物经验!C30 -> 192500 | H30: =任务经验!F30 -> 4400 | I30: 20 | J30: =LOOKUP(I30,组队副本!A:A,组队副本!I:I) -> 58800 | K30: =J30*E30*$R$5 -> 102900 | M30: 299800
A31: 30 | B31: =G31+H31+K31 -> 432680 | C31: =ROUND(B31,-2) -> 432700 | D31: =D30+10 -> 360 | E31: =D31/$R$4 -> 0.36 | F31: =SUM($E$2:E31) -> 4.89 | G31: =D31*怪物经验!C31 -> 208800 | H31: =任务经验!F31 -> 4640 | I31: 30 | J31: =LOOKUP(I31,组队副本!A:A,组队副本!I:I) -> 121800 | K31: =J31*E31*$R$5 -> 219240 | M31: 432680
A32: 31 | B32: =G32+H32+K32 -> 456520 | C32: =ROUND(B32,-2) -> 456500 | D32: =D31+10 -> 370 | E32: =D32/$R$4 -> 0.37 | F32: =SUM($E$2:E32) -> 5.26 | G32: =D32*怪物经验!C32 -> 225700 | H32: =任务经验!F32 -> 5490 | I32: 30 | J32: =LOOKUP(I32,组队副本!A:A,组队副本!I:I) -> 121800 | K32: =J32*E32*$R$5 -> 225330 | M32: 456520
A33: 32 | B33: =G33+H33+K33 -> 480380 | C33: =ROUND(B33,-2) -> 480400 | D33: =D32+10 -> 380 | E33: =D33/$R$4 -> 0.38 | F33: =SUM($E$2:E33) -> 5.64 | G33: =D33*怪物经验!C33 -> 243200 | H33: =任务经验!F33 -> 5760 | I33: 30 | J33: =LOOKUP(I33,组队副本!A:A,组队副本!I:I) -> 121800 | K33: =J33*E33*$R$5 -> 231420 | M33: 480380
A34: 33 | B34: =G34+H34+K34 -> 504840 | C34: =ROUND(B34,-2) -> 504800 | D34: =D33+10 -> 390 | E34: =D34/$R$4 -> 0.39 | F34: =SUM($E$2:E34) -> 6.03 | G34: =D34*怪物经验!C34 -> 261300 | H34: =任务经验!F34 -> 6030 | I34: 30 | J34: =LOOKUP(I34,组队副本!A:A,组队副本!I:I) -> 121800 | K34: =J34*E34*$R$5 -> 237510 | M34: 504840
A35: 34 | B35: =G35+H35+K35 -> 529900 | C35: =ROUND(B35,-2) -> 529900 | D35: =D34+10 -> 400 | E35: =D35/$R$4 -> 0.4 | F35: =SUM($E$2:E35) -> 6.43 | G35: =D35*怪物经验!C35 -> 280000 | H35: =任务经验!F35 -> 6300 | I35: 30 | J35: =LOOKUP(I35,组队副本!A:A,组队副本!I:I) -> 121800 | K35: =J35*E35*$R$5 -> 243600 | M35: 529900
A36: 35 | B36: =G36+H36+K36 -> 555560 | C36: =ROUND(B36,-2) -> 555600 | D36: =D35+10 -> 410 | E36: =D36/$R$4 -> 0.41 | F36: =SUM($E$2:E36) -> 6.84 | G36: =D36*怪物经验!C36 -> 299300 | H36: =任务经验!F36 -> 6570 | I36: 30 | J36: =LOOKUP(I36,组队副本!A:A,组队副本!I:I) -> 121800 | K36: =J36*E36*$R$5 -> 249690 | M36: 555560
A37: 36 | B37: =G37+H37+K37 -> 582580 | C37: =ROUND(B37,-2) -> 582600 | D37: =D36+10 -> 420 | E37: =D37/$R$4 -> 0.42 | F37: =SUM($E$2:E37) -> 7.26 | G37: =D37*怪物经验!C37 -> 319200 | H37: =任务经验!F37 -> 7600 | I37: 30 | J37: =LOOKUP(I37,组队副本!A:A,组队副本!I:I) -> 121800 | K37: =J37*E37*$R$5 -> 255780 | M37: 582580
A38: 37 | B38: =G38+H38+K38 -> 609470 | C38: =ROUND(B38,-2) -> 609500 | D38: =D37+10 -> 430 | E38: =D38/$R$4 -> 0.43 | F38: =SUM($E$2:E38) -> 7.69 | G38: =D38*怪物经验!C38 -> 339700 | H38: =任务经验!F38 -> 7900 | I38: 30 | J38: =LOOKUP(I38,组队副本!A:A,组队副本!I:I) -> 121800 | K38: =J38*E38*$R$5 -> 261870 | M38: 609470
A39: 38 | B39: =G39+H39+K39 -> 636960 | C39: =ROUND(B39,-2) -> 637000 | D39: =D38+10 -> 440 | E39: =D39/$R$4 -> 0.44 | F39: =SUM($E$2:E39) -> 8.13 | G39: =D39*怪物经验!C39 -> 360800 | H39: =任务经验!F39 -> 8200 | I39: 30 | J39: =LOOKUP(I39,组队副本!A:A,组队副本!I:I) -> 121800 | K39: =J39*E39*$R$5 -> 267960 | M39: 636960
A40: 39 | B40: =G40+H40+K40 -> 738000 | C40: =ROUND(B40,-2) -> 738000 | D40: 500 | E40: =D40/$R$4 -> 0.5 | F40: =SUM($E$2:E40) -> 8.63 | G40: =D40*怪物经验!C40 -> 425000 | H40: =任务经验!F40 -> 8500 | I40: 30 | J40: =LOOKUP(I40,组队副本!A:A,组队副本!I:I) -> 121800 | K40: =J40*E40*$R$5 -> 304500 | M40: 738000
...

Sheet 家族经验
B2: 等级 | C2: 每天经验产出 | D2: 系数 | F2: 经验修 | G2: 人员上限 | H2: 累计捐献次数 | I2: 捐献满人次 | J2: 捐献金币 | M2: 单次任务经验 | N2: 5 | O2: ’2-8 | Q2: 家族捐献 | R2: 5 | T2: 家族捐献 | V2: 家族等级 | W2: 每天捐献 | X2: 系数 | Y2: 经验
B3: 1 | C3: =G3*$N$2*10 -> 750 | D3: 0.7 | E3: =D3*C3 -> 525 | F3: =ROUND(E3,-2) -> 500 | G3: 15 | H3: =F3/$N$3 -> 25 | I3: =H3/$N$4 -> 5 | J3: 200000 | M3: 单次捐献 | N3: 20 | O3: ‘10-30 | Q3: 家族捐献 | R3: 10 | T3: 50 | V3: 1 | W3: 100 | X3: 1 | Y3: =X3*W3 -> 100
B4: 2 | C4: =G4*$N$2*10 -> 900 | D4: 1.15 | E4: =D4*C4 -> 1035 | F4: =ROUND(E4,-2) -> 1000 | G4: 18 | H4: =F4/$N$3 -> 50 | I4: =H4/$N$4 -> 10 | J4: =J3+20000 -> 220000 | M4: 每天捐献上限 | N4: 5 | V4: 2 | W4: 100 | X4: 2 | Y4: =X4*W4 -> 200
B5: 3 | C5: =G5*$N$2*10 -> 1050 | D5: 1.7 | E5: =D5*C5 -> 1785 | F5: =ROUND(E5,-2) -> 1800 | G5: 21 | H5: =F5/$N$3 -> 90 | I5: =H5/$N$4 -> 18 | J5: =J4+20000 -> 240000 | V5: 3 | W5: 100 | X5: 3 | Y5: =X5*W5 -> 300
B6: 4 | C6: =G6*$N$2*10 -> 1200 | D6: =D5+0.6 -> 2.3 | E6: =D6*C6 -> 2760 | F6: =ROUND(E6,-2) -> 2800 | G6: 24 | H6: =F6/$N$3 -> 140 | I6: =H6/$N$4 -> 28 | J6: =J5+20000 -> 260000 | V6: 4 | W6: 100 | X6: 4 | Y6: =X6*W6 -> 400
B7: 5 | C7: =G7*$N$2*10 -> 1350 | D7: =D6+0.65 -> 2.95 | E7: =D7*C7 -> 3982.5 | F7: =ROUND(E7,-2) -> 4000 | G7: 27 | H7: =F7/$N$3 -> 200 | I7: =H7/$N$4 -> 40 | J7: =J6+20000 -> 280000 | V7: 5 | W7: 100 | X7: 5 | Y7: =X7*W7 -> 500
B8: 6 | C8: =G8*$N$2*10 -> 1500 | D8: =D7+0.7 -> 3.65 | E8: =D8*C8 -> 5475 | F8: =ROUND(E8,-2) -> 5500 | G8: 30 | H8: =F8/$N$3 -> 275 | I8: =H8/$N$4 -> 55 | J8: =J7+20000 -> 300000 | V8: 6 | W8: 100 | X8: 6 | Y8: =X8*W8 -> 600
B9: 7 | C9: =G9*$N$2*10 -> 1650 | D9: =D8+0.9 -> 4.55 | E9: =D9*C9 -> 7507.5 | F9: =ROUND(E9,-2) -> 7500 | G9: 33 | H9: =F9/$N$3 -> 375 | I9: =H9/$N$4 -> 75 | J9: =J8+20000 -> 320000 | V9: 7 | W9: 100 | X9: 7 | Y9: =X9*W9 -> 700
B10: 8 | C10: =G10*$N$2*10 -> 1800 | D10: =D9+1 -> 5.55 | E10: =D10*C10 -> 9990 | F10: =ROUND(E10,-2) -> 10000 | G10: 36 | H10: =F10/$N$3 -> 500 | I10: =H10/$N$4 -> 100 | J10: =J9+20000 -> 340000 | V10: 8 | W10: 100 | X10: 8 | Y10: =X10*W10 -> 800
B11: 9 | C11: =G11*$N$2*10 -> 1900 | D11: =D10+1.3 -> 6.85 | E11: =D11*C11 -> 13015 | F11: =ROUND(E11,-2) -> 13000 | G11: 38 | H11: =F11/$N$3 -> 650 | I11: =H11/$N$4 -> 130 | J11: =J10+30000 -> 370000 | V11: 9 | W11: 100 | X11: 9 | Y11: =X11*W11 -> 900
B12: 10 | C12: =G12*$N$2*10 -> 2000 | D12: =D11+1.4 -> 8.25 | E12: =D12*C12 -> 16500 | F12: =ROUND(E12,-2) -> 16500 | G12: 40 | H12: =F12/$N$3 -> 825 | I12: =H12/$N$4 -> 165 | J12: =J11+30000 -> 400000 | V12: 10 | W12: 100 | X12: 10 | Y12: =X12*W12 -> 1000
D14: =SUM(D3:D11) -> 29.4 | X14: =SUM(X3:X12) -> 55
W15: 总天数 | X15: =X14*4 -> 220
M16: 修炼能力
M17: 攻击 | O17: 1 | P17: 50 | S17: =P17*6 -> 300 | U17: ="100403;"&P17 -> 100403;50 | X17: ="100203;"&S17 -> 100203;300
M18: 防御 | O18: 2 | P18: 100 | Q18: =P18-P17 -> 50 | S18: =P18*6 -> 600 | U18: ="100403;"&P18 -> 100403;100 | X18: ="100203;"&S18 -> 100203;600
B19: 任务 | M19: 血量 | O19: 3 | P19: 200 | Q19: =P19-P18 -> 100 | S19: =P19*6 -> 1200 | U19: ="100403;"&P19 -> 100403;200 | X19: ="100203;"&S19 -> 100203;1200
B20: 1 | C20: 随机杀怪 | M20: 魔防 | O20: 4 | P20: 350 | Q20: =P20-P19 -> 150 | S20: =P20*6 -> 2100 | U20: ="100403;"&P20 -> 100403;350 | X20: ="100203;"&S20 -> 100203;2100
B21: 2 | C21: 随机要东西 | M21: 法术 | O21: 5 | P21: 500 | Q21: =P21-P20 -> 150 | S21: =P21*6 -> 3000 | U21: ="100403;"&P21 -> 100403;500 | X21: ="100203;"&S21 -> 100203;3000
B22: 3 | O22: 6 | P22: 700 | Q22: =P22-P21 -> 200 | S22: =P22*6 -> 4200 | U22: ="100403;"&P22 -> 100403;700 | X22: ="100203;"&S22 -> 100203;4200
O23: 7 | P23: 900 | Q23: =P23-P22 -> 200 | S23: =P23*6 -> 5400 | U23: ="100403;"&P23 -> 100403;900 | X23: ="100203;"&S23 -> 100203;5400
O24: 8 | P24: 1200 | Q24: =P24-P23 -> 300 | S24: =P24*6 -> 7200 | U24: ="100403;"&P24 -> 100403;1200 | X24: ="100203;"&S24 -> 100203;7200
O25: 9 | P25: 1500 | Q25: =P25-P24 -> 300 | S25: =P25*6 -> 9000 | U25: ="100403;"&P25 -> 100403;1500 | X25: ="100203;"&S25 -> 100203;9000
O26: 10 | P26: 1800 | Q26: =P26-P25 -> 300 | S26: =P26*6 -> 10800 | U26: ="100403;"&P26 -> 100403;1800 | X26: ="100203;"&S26 -> 100203;10800
J27: 捐献金额的50%累计
C29: 家族捐献 | D29: 游戏爆率 | E29: 对怪伤害加成
C30: 1 | D30: 25 | E30: 30 | F30: 王者捐献 | H30: 5%暴击 | K30: 5000000
C31: 2 | D31: 20 | E31: 25 | F31: 钻石捐献
C32: 3 | D32: 15 | E32: 20 | F32: 黄金捐献 | K32: =K30*0.8*0.6/20 -> 120000 | U32: 0.1
C33: 4-5 | D33: 10 | E33: 15 | F33: 白银捐献 | Q33: =200*12 -> 2400
C34: 6-10 | D34: 5 | E34: 10 | F34: 青铜捐献
C35: 其他 | D35: 5 | E35: 5 | F35: 爱心捐献
J36: 获胜家族名字带(冠军)
O39: 玩家血量 | P39: 0.15 | T39: 0.225 | U39: 优化 | X39: 慢性恢复 | Y39: 0.3
I40: 立即恢复1200点生命 | L40: 2500 | O40: 10000 | P40: =O40*$P$39 -> 1500 | Q40: 2000 | T40: =O40*$T$39 -> 2250 | U40: =T40 -> 2250 | Y40: =O40*$Y$39 -> 3000 | Z40: =Y40/12 -> 250
I41: 立即恢复2400点生命 | L41: 4000 | M41: =L41-L40 -> 1500 | O41: 20000 | P41: =O41*$P$39 -> 3000 | Q41: 4000 | R41: =Q41-Q40 -> 2000 | T41: =O41*$T$39 -> 4500 | U41: =T41 -> 4500 | V41: =U41-U40 -> 2250 | Y41: =O41*$Y$39 -> 6000 | Z41: =Y41/12 -> 500
I42: 立即恢复4000点生命 | L42: 6000 | M42: =L42-L41 -> 2000 | O42: 40000 | P42: =O42*$P$39 -> 6000 | Q42: 7500 | R42: =Q42-Q41 -> 3500 | T42: =O42*$T$39 -> 9000 | U42: =T42 -> 9000 | V42: =U42-U41 -> 4500 | Y42: =O42*$Y$39 -> 12000 | Z42: =Y42/12 -> 1000
I43: 立即恢复6000点生命 | L43: 9000 | M43: =L43-L42 -> 3000 | O43: 60000 | P43: =O43*$P$39 -> 9000 | Q43: 12000 | R43: =Q43-Q42 -> 4500 | T43: =O43*$T$39 -> 13500 | U43: =T43 -> 13500 | V43: =U43-U42 -> 4500 | Y43: =O43*$Y$39 -> 18000 | Z43: =Y43/12 -> 1500
I44: 立即恢复8000点生命 | L44: 12000 | M44: =L44-L43 -> 3000 | O44: 80000 | P44: =O44*$P$39 -> 12000 | Q44: 18000 | R44: =Q44-Q43 -> 6000 | T44: =O44*$T$39 -> 18000 | U44: =T44 -> 18000 | V44: =U44-U43 -> 4500 | Y44: =O44*$Y$39 -> 24000 | Z44: =Y44/12 -> 2000
L45: 35000 | M45: =L45-L44 -> 23000 | O45: 120000 | P45: =O45*$P$39 -> 18000 | Q45: 24000 | R45: =Q45-Q44 -> 6000 | T45: =O45*$T$39 -> 27000 | U45: =T45 -> 27000 | V45: =U45-U44 -> 9000 | Y45: =O45*$Y$39 -> 36000 | Z45: =Y45/12 -> 3000

Sheet Sheet1
B3: 世界等级
B4: 1 | C4: 18
B5: 2 | C5: 25
B6: 3 | C6: 30
B7: 4 | C7: 35
B8: 5 | C8: 40
B9: 6 | C9: 45
B10: 7 | C10: 50
B11: 8 | C11: 55
B12: 9 | C12: 58
B13: 10 | C13: 60

Sheet 怪物经验
A1: 怪物等级 | C1: 普通怪 | D1: 低等BOSS经验 | E1: 中等BOSS经验 | F1: 高等BOSS经验 | G1: 最高BOSS经验 | K1: 等级 | L1: 类型 | M1: 普通 | N1: boss
A2: 1 | B2: 5 | C2: 15 | D2: =C2*2 -> 30 | E2: =C2*2 -> 30 | F2: =C2*2 -> 30 | G2: =C2*10 -> 150 | K2: 1 | L2: 1 | M2: =IF(L2=1,LOOKUP(K2,A:A,C:C),"") -> 15 | N2: =IF(L2=3,LOOKUP(K2,A:A,G:G),"") | O2: =IF(M2="",N2,M2) -> 15
A3: 2 | B3: 5 | C3: =C2+B3 -> 20 | D3: =C3*2 -> 40 | E3: =C3*2 -> 40 | F3: =C3*2 -> 40 | G3: =C3*20 -> 400 | K3: 2 | L3: 1 | M3: =IF(L3=1,LOOKUP(K3,A:A,C:C),"") -> 20 | N3: =IF(L3=3,LOOKUP(K3,A:A,G:G),"") | O3: =IF(M3="",N3,M3) -> 20
A4: 3 | B4: 5 | C4: =C3+B4 -> 25 | D4: =C4*2 -> 50 | E4: =C4*2 -> 50 | F4: =C4*2 -> 50 | G4: =C4*20 -> 500 | K4: 3 | L4: 1 | M4: =IF(L4=1,LOOKUP(K4,A:A,C:C),"") -> 25 | N4: =IF(L4=3,LOOKUP(K4,A:A,G:G),"") | O4: =IF(M4="",N4,M4) -> 25
A5: 4 | B5: 5 | C5: =C4+B5 -> 30 | D5: =C5*2 -> 60 | E5: =C5*2 -> 60 | F5: =C5*2 -> 60 | G5: =C5*20 -> 600 | K5: 3 | L5: 3 | M5: =IF(L5=1,LOOKUP(K5,A:A,C:C),"") | N5: =IF(L5=3,LOOKUP(K5,A:A,G:G),"") -> 500 | O5: =IF(M5="",N5,M5) -> 500
A6: 5 | B6: 10 | C6: =C5+B6 -> 40 | D6: =C6*2 -> 80 | E6: =C6*2 -> 80 | F6: =C6*2 -> 80 | G6: =C6*20 -> 800 | K6: 4 | L6: 1 | M6: =IF(L6=1,LOOKUP(K6,A:A,C:C),"") -> 30 | N6: =IF(L6=3,LOOKUP(K6,A:A,G:G),"") | O6: =IF(M6="",N6,M6) -> 30
A7: 6 | B7: 10 | C7: =C6+B7 -> 50 | D7: =C7*2 -> 100 | E7: =C7*2 -> 100 | F7: =C7*2 -> 100 | G7: =C7*20 -> 1000 | K7: 4 | L7: 1 | M7: =IF(L7=1,LOOKUP(K7,A:A,C:C),"") -> 30 | N7: =IF(L7=3,LOOKUP(K7,A:A,G:G),"") | O7: =IF(M7="",N7,M7) -> 30
A8: 7 | B8: 10 | C8: =C7+B8 -> 60 | D8: =C8*2 -> 120 | E8: =C8*2 -> 120 | F8: =C8*2 -> 120 | G8: =C8*20 -> 1200 | K8: 4 | L8: 1 | M8: =IF(L8=1,LOOKUP(K8,A:A,C:C),"") -> 30 | N8: =IF(L8=3,LOOKUP(K8,A:A,G:G),"") | O8: =IF(M8="",N8,M8) -> 30
A9: 8 | B9: 10 | C9: =C8+B9 -> 70 | D9: =C9*2 -> 140 | E9: =C9*2 -> 140 | F9: =C9*2 -> 140 | G9: =C9*20 -> 1400 | K9: 4 | L9: 1 | M9: =IF(L9=1,LOOKUP(K9,A:A,C:C),"") -> 30 | N9: =IF(L9=3,LOOKUP(K9,A:A,G:G),"") | O9: =IF(M9="",N9,M9) -> 30
A10: 9 | B10: 10 | C10: =C9+B10 -> 80 | D10: =C10*2 -> 160 | E10: =C10*2 -> 160 | F10: =C10*2 -> 160 | G10: =C10*20 -> 1600 | K10: 5 | L10: 3 | M10: =IF(L10=1,LOOKUP(K10,A:A,C:C),"") | N10: =IF(L10=3,LOOKUP(K10,A:A,G:G),"") -> 800 | O10: =IF(M10="",N10,M10) -> 800
A11: 10 | B11: 15 | C11: =C10+B11 -> 95 | D11: =C11*2 -> 190 | E11: =C11*2 -> 190 | F11: =C11*2 -> 190 | G11: =C11*20 -> 1900 | K11: 7 | L11: 1 | M11: =IF(L11=1,LOOKUP(K11,A:A,C:C),"") -> 60 | N11: =IF(L11=3,LOOKUP(K11,A:A,G:G),"") | O11: =IF(M11="",N11,M11) -> 60
A12: 11 | B12: 15 | C12: =C11+B12 -> 110 | D12: =C12*2 -> 220 | E12: =C12*2 -> 220 | F12: =C12*2 -> 220 | G12: =C12*20 -> 2200 | K12: 7 | L12: 1 | M12: =IF(L12=1,LOOKUP(K12,A:A,C:C),"") -> 60 | N12: =IF(L12=3,LOOKUP(K12,A:A,G:G),"") | O12: =IF(M12="",N12,M12) -> 60
A13: 12 | B13: 15 | C13: =C12+B13 -> 125 | D13: =C13*2 -> 250 | E13: =C13*2 -> 250 | F13: =C13*2 -> 250 | G13: =C13*20 -> 2500 | K13: 8 | L13: 1 | M13: =IF(L13=1,LOOKUP(K13,A:A,C:C),"") -> 70 | N13: =IF(L13=3,LOOKUP(K13,A:A,G:G),"") | O13: =IF(M13="",N13,M13) -> 70
A14: 13 | B14: 15 | C14: =C13+B14 -> 140 | D14: =C14*2 -> 280 | E14: =C14*2 -> 280 | F14: =C14*2 -> 280 | G14: =C14*20 -> 2800 | K14: 10 | L14: 3 | M14: =IF(L14=1,LOOKUP(K14,A:A,C:C),"") | N14: =IF(L14=3,LOOKUP(K14,A:A,G:G),"") -> 1900 | O14: =IF(M14="",N14,M14) -> 1900
... A76: 75 | B76: 30 | C76: =C75+B76 -> 1930 | D76: =C76*2 -> 3860 | E76: =C76*2 -> 3860 | F76: =C76*2 -> 3860 | G76: =C76*20 -> 38600 | K76: 60 | L76: 3 | M76: =IF(L76=1,LOOKUP(K76,A:A,C:C),"") | N76: =IF(L76=3,LOOKUP(K76,A:A,G:G),"") -> 29600 | O76: =IF(M76="",N76,M76) -> 29600
A77: 76 | B77: 30 | C77: =C76+B77 -> 1960 | D77: =C77*2 -> 3920 | E77: =C77*2 -> 3920 | F77: =C77*2 -> 3920 | G77: =C77*20 -> 39200
A78: 77 | B78: 30 | C78: =C77+B78 -> 1990 | D78: =C78*2 -> 3980 | E78: =C78*2 -> 3980 | F78: =C78*2 -> 3980 | G78: =C78*20 -> 39800
A79: 78 | B79: 30 | C79: =C78+B79 -> 2020 | D79: =C79*2 -> 4040 | E79: =C79*2 -> 4040 | F79: =C79*2 -> 4040 | G79: =C79*20 -> 40400
A80: 79 | B80: 30 | C80: =C79+B80 -> 2050 | D80: =C80*2 -> 4100 | E80: =C80*2 -> 4100 | F80: =C80*2 -> 4100 | G80: =C80*20 -> 41000
A81: 80 | B81: 30 | C81: =C80+B81 -> 2080 | D81: =C81*2 -> 4160 | E81: =C81*2 -> 4160 | F81: =C81*2 -> 4160 | G81: =C81*20 -> 41600

Sheet 任务经验
A1: 任务等级 | B1: 经验系数 | C1: 任务经验 | D1: 当前等级任务数 | E1: 修正任务数 | F1: 任务经验
A2: 1 | B2: 5 | C2: =B2*[1]怪物经验!C2 -> 75 | D2: 2 | E2: 2 | F2: =E2*C2 -> 150 | I2: 1 | J2: =VLOOKUP(I2,$A$2:$C$66,3,FALSE) -> 75
A3: 2 | B3: 5 | C3: =B3*[1]怪物经验!C3 -> 100 | D3: 1 | E3: 3 | F3: =E3*C3 -> 300 | I3: 1 | J3: =VLOOKUP(I3,$A$2:$C$66,3,FALSE) -> 75
A4: 3 | B4: 5 | C4: =B4*[1]怪物经验!C4 -> 125 | D4: 10 | E4: 5 | F4: =E4*C4 -> 625 | I4: 2 | J4: =VLOOKUP(I4,$A$2:$C$66,3,FALSE) -> 100
A5: 4 | B5: 5 | C5: =B5*[1]怪物经验!C5 -> 150 | D5: 4 | E5: 3 | F5: =E5*C5 -> 450 | I5: 3 | J5: =VLOOKUP(I5,$A$2:$C$66,3,FALSE) -> 125
A6: 5 | B6: 5 | C6: =B6*[1]怪物经验!C6 -> 200 | D6: 3 | E6: 3 | F6: =E6*C6 -> 600 | I6: 3 | J6: =VLOOKUP(I6,$A$2:$C$66,3,FALSE) -> 125
A7: 6 | B7: 5 | C7: =B7*[1]怪物经验!C7 -> 250 | D7: 2 | E7: 2 | F7: =E7*C7 -> 500 | I7: 3 | J7: =VLOOKUP(I7,$A$2:$C$66,3,FALSE) -> 125
A8: 7 | B8: 5 | C8: =B8*[1]怪物经验!C8 -> 300 | D8: 2 | E8: 2 | F8: =E8*C8 -> 600 | I8: 3 | J8: =VLOOKUP(I8,$A$2:$C$66,3,FALSE) -> 125
A9: 8 | B9: 5 | C9: =B9*[1]怪物经验!C9 -> 350 | D9: 2 | E9: 2 | F9: =E9*C9 -> 700 | I9: 3 | J9: =VLOOKUP(I9,$A$2:$C$66,3,FALSE) -> 125
A10: 9 | B10: 5 | C10: =B10*[1]怪物经验!C10 -> 400 | D10: 1 | E10: 1 | F10: =E10*C10 -> 400 | I10: 3 | J10: =VLOOKUP(I10,$A$2:$C$66,3,FALSE) -> 125
A11: 10 | B11: 5 | C11: =B11*[1]怪物经验!C11 -> 475 | D11: 1 | E11: 1 | F11: =E11*C11 -> 475 | I11: 3 | J11: =VLOOKUP(I11,$A$2:$C$66,3,FALSE) -> 125
A12: 11 | B12: 6 | C12: =B12*[1]怪物经验!C12 -> 660 | D12: 1 | E12: 1 | F12: =E12*C12 -> 660 | I12: 3 | J12: =VLOOKUP(I12,$A$2:$C$66,3,FALSE) -> 125
A13: 12 | B13: 6 | C13: =B13*[1]怪物经验!C13 -> 750 | D13: 1 | E13: 1 | F13: =E13*C13 -> 750 | I13: 3 | J13: =VLOOKUP(I13,$A$2:$C$66,3,FALSE) -> 125
... A34: 33 | B34: 9 | C34: =B34*[1]怪物经验!C34 -> 6030 | D34: 1 | E34: 1 | F34: =E34*C34 -> 6030 | I34: 15 | J34: =VLOOKUP(I34,$A$2:$C$66,3,FALSE) -> 1020
A35: 34 | B35: 9 | C35: =B35*[1]怪物经验!C35 -> 6300 | D35: 1 | E35: 1 | F35: =E35*C35 -> 6300
A36: 35 | B36: 9 | C36: =B36*[1]怪物经验!C36 -> 6570 | D36: 1 | E36: 1 | F36: =E36*C36 -> 6570
A37: 36 | B37: 10 | C37: =B37*[1]怪物经验!C37 -> 7600 | D37: 1 | E37: 1 | F37: =E37*C37 -> 7600
A38: 37 | B38: 10 | C38: =B38*[1]怪物经验!C38 -> 7900 | D38: 1 | E38: 1 | F38: =E38*C38 -> 7900
A39: 38 | B39: 10 | C39: =B39*[1]怪物经验!C39 -> 8200 | D39: 1 | E39: 1 | F39: =E39*C39 -> 8200
A40: 39 | B40: 10 | C40: =B40*[1]怪物经验!C40 -> 8500 | D40: 1 | E40: 1 | F40: =E40*C40 -> 8500
A41: 40 | B41: 10 | C41: =B41*[1]怪物经验!C41 -> 8800 | D41: 1 | E41: 1 | F41: =E41*C41 -> 8800
A42: 41 | B42: 10 | C42: =B42*[1]怪物经验!C42 -> 9100 | D42: 1 | E42: 1 | F42: =E42*C42 -> 9100
A43: 42 | B43: 10 | C43: =B43*[1]怪物经验!C43 -> 9400 | D43: 1 | E43: 1 | F43: =E43*C43 -> 9400
A44: 43 | B44: 10 | C44: =B44*[1]怪物经验!C44 -> 9700 | D44: 1 | E44: 1 | F44: =E44*C44 -> 9700
A45: 44 | B45: 10 | C45: =B45*[1]怪物经验!C45 -> 10000 | D45: 1 | E45: 1 | F45: =E45*C45 -> 10000
A46: 45 | B46: 10 | C46: =B46*[1]怪物经验!C46 -> 10300 | D46: 1 | E46: 1 | F46: =E46*C46 -> 10300
... A101: 100 | B101: 10 | C101: =B101*[1]怪物经验!C101 -> 0 | D101: 1 | E101: 1 | F101: =E101*C101 -> 0

Sheet 组队副本
A1: 副本等级 | B1: 对应怪物经验 | C1: 副本怪物经验系数 | E1: 副本BOSS经验系数 | G1: 副本通关经验系数 | I1: 累计总经验
A2: 20 | B2: =LOOKUP(A2,怪物经验!A:A,怪物经验!C:C) -> 280 | C2: 1 | D2: =B2*C2 -> 280 | E2: 20 | F2: =E2*B2 -> 5600 | G2: 100 | H2: =G2*B2 -> 28000 | I2: =H2+F2*$Q$3+D2*$Q$2 -> 58800 | P2: 副本怪物数量 | Q2: 50
A3: 30 | B3: =LOOKUP(A3,怪物经验!A:A,怪物经验!C:C) -> 580 | C3: 1 | D3: =B3*C3 -> 580 | E3: 20 | F3: =E3*B3 -> 11600 | G3: 100 | H3: =G3*B3 -> 58000 | I3: =H3+F3*$Q$3+D3*$Q$2 -> 121800 | P3: 副本BOSS数量 | Q3: 3
A4: 40 | B4: =LOOKUP(A4,怪物经验!A:A,怪物经验!C:C) -> 880 | C4: 1 | D4: =B4*C4 -> 880 | E4: 20 | F4: =E4*B4 -> 17600 | G4: 100 | H4: =G4*B4 -> 88000 | I4: =H4+F4*$Q$3+D4*$Q$2 -> 184800
A5: 50 | B5: =LOOKUP(A5,怪物经验!A:A,怪物经验!C:C) -> 1180 | C5: 1 | D5: =B5*C5 -> 1180 | E5: 20 | F5: =E5*B5 -> 23600 | G5: 100 | H5: =G5*B5 -> 118000 | I5: =H5+F5*$Q$3+D5*$Q$2 -> 247800
